Workbook
Name liste_niveau: LISTES!$A$3:$A$6
Name liste_statut_nageur: LISTES!$B$3:$B$6
Name liste_sexe: LISTES!$C$3:$C$4
Name liste_cadre: LISTES!$D$3:$D$4
Name liste_bassin: LISTES!$E$3:$E$4
Name liste_oui_non: LISTES!$F$3:$F$4
Name liste_discipline: LISTES!$G$3:$G$8
Name liste_nage: LISTES!$H$3:$H$7
Name liste_priorite: LISTES!$I$3:$I$4
Name liste_statut_objectif: LISTES!$J$3:$J$6
Name liste_protocole: LISTES!$K$3:$K$8
Name liste_depart: LISTES!$L$3:$L$5
Name liste_contexte: LISTES!$M$3:$M$5
Name liste_forme: LISTES!$N$3:$N$6
Name liste_bassin_lieu: LISTES!$O$3:$O$5
Name liste_theme_seance: LISTES!$P$3:$P$10
Name liste_faite_seance: LISTES!$Q$3:$Q$5
Name liste_type_semaine: LISTES!$R$3:$R$6
Name liste_qualite: LISTES!$S$3:$S$5

Sheet GUIDE
B2: SUIVI NAGEURS — COACH DE LIGNE
B3: Excel 365 (Mac ou Windows). Jaune = tu saisis. Gris = formule, ne pas écraser. Léa / Thomas / Inès sont des EXEMPLES — remplace-les par tes nageurs.
B5: 1. Logique
B6: 1 ligne dans NAGEURS, 1 objectif A dans OBJECTIFS, 1 ligne par chrono dans TESTS (on n’écrase jamais un temps). Le DASHBOARD se calcule tout seul. EXPORT reprend les champs utiles pour MySWYM (T100, cible, date).
B9: 2. Batterie A — vitesse (toutes les 4–5 semaines)
B10: Même échauffement à chaque fois (600–800 m). T50 à fond, récup 6–8 min, T100 à fond. Noter bassin (25/50), départ (plongé / poussée), nage. Pas de 400 le même jour.
B13: 3. Batterie B — aérobie (toutes les 6–8 semaines)
B14: T200 quasi max régulier, récup 10–15 min, T400. CSS = (T400 − T200) / 2 (allure seuil aux 100 m). Utile 400 / triathlon / eau libre. MySWYM n’utilise que le T100 ; le 400 est pour toi.
B17: 4. Saisie des temps
B18: 1:12.50 ou 34.8 ou 0:34.80. Virgule française 1:12,50 acceptée. Splits 50 / 100 optionnels, précieux pour voir où ça casse.
B21: 5. Un seul objectif A
B22: Priorité A + statut en_cours = ce que le dashboard affiche. Un B possible. À 8–10 semaines : spécifique. À moins de 3 semaines : plus de test à fond.
... B30: 1 ligne par séance dans SEANCES (1 à 5 / semaine). CHARGE agrège par semaine. Deload : 3 semaines de charge puis 1 allégée (−30 % vol, RPE ≤ 6). Retest A (T50+T100) après 4–5 sem, Batterie B après 6–8 sem — jamais pendant un deload ni < 3 sem avant l’objectif.
B33: Onglet | C33: Rôle
B34: DASHBOARD | C34: Lecture dimanche : temps + deload + retest.
B35: NAGEURS | C35: 1 ligne = 1 personne. id stable (N001…).
B36: OBJECTIFS | C36: 1 ligne = 1 course / diplôme.
B37: TESTS | C37: 1 ligne = 1 chrono. Cœur du suivi.
B38: SEANCES | C38: 1 ligne = 1 séance (1 à 5 / semaine).
B39: CHARGE | C39: 1 ligne = 1 nageur × 1 semaine. Alertes auto.
B40: EVOLUTION | C40: Courbe T100 d’exemple (Léa).
B41: EXPORT | C41: Colonnes app — ne pas saisir.
B43: Jaune = saisie | C43: Gris = formule

Sheet DASHBOARD
A1: TABLEAU DE BORD — tests · charge · deload · retest · ne rien saisir ici
A2: id | B2: prenom | C2: nom | D2: niveau | E2: statut | F2: nage_suivi | G2: discipline | H2: nage_obj | I2: dist_m | J2: date_obj | K2: lieu | L2: cible | M2: semaines | N2: T50 | O2: T100 | P2: T200 | Q2: T400 | R2: delta_T100 | S2: drop_100/50 | T2: drop_400/100 | U2: CSS_/100 | V2: T100_sec | W2: diagnostic | X2: seances_S | Y2: vol_S | Z2: vol_S/S-1/S-2 | AA2: deload | AB2: retest | AC2: consigne_charge
A3: =IFERROR(IF(INDEX(tblNageurs[id],1)="","",INDEX(tblNageurs[id],1)),"") | B3: =IF($A3="","",IFERROR(INDEX(tblNageurs[prenom],1),"")) | C3: =IF($A3="","",IFERROR(INDEX(tblNageurs[nom],1),"")) | D3: =IF($A3="","",IFERROR(INDEX(tblNageurs[niveau],1),"")) | E3: =IF($A3="","",IFERROR(INDEX(tblNageurs[statut],1),"")) | F3: =IF($A3="","",IF(OR($H3="dos",$H3="brasse",$H3="papillon"),$H3,"crawl")) | G3: =IF($A3="","",IFERROR(XLOOKUP($A3,tblObjectifs[cle_dashboard],tblObjectifs[discipline],""),"")) | H3: =IF($A3="","",IFERROR(XLOOKUP($A3,tblObjectifs[cle_dashboard],tblObjectifs[nage],""),"")) | I3: =IF($A3="","",IFERROR(XLOOKUP($A3,tblObjectifs[cle_dashboard],tblObjectifs[distance_m],""),"")) | J3: =IF($A3="","",IFERROR(XLOOKUP($A3,tblObjectifs[cle_dashboard],tblObjectifs[date_objectif],""),"")) | K3: =IF($A3="","",IFERROR(XLOOKUP($A3,tblObjectifs[cle_dashboard],tblObjectifs[lieu],""),"")) | L3: =IF($A3="","",IFERROR(XLOOKUP($A3,tblObjectifs[cle_dashboard],tblObjectifs[temps_cible],""),"")) | M3: =IF(OR($A3="",$J3=""),"",($J3-TODAY())/7) | N3: =IF(BA3="","",INT(BA3/60)&":"&TEXT(MOD(BA3,60),"00.00")) | O3: =IF(BB3="","",INT(BB3/60)&":"&TEXT(MOD(BB3,60),"00.00")) | P3: =IF(BC3="","",INT(BC3/60)&":"&TEXT(MOD(BC3,60),"00.00")) | Q3: =IF(BD3="","",INT(BD3/60)&":"&TEXT(MOD(BD3,60),"00.00")) | R3: =IF(OR(BB3="",BE3=""),"",(BB3-BE3)/BE3) | S3: =IF(OR(BA3="",BB3=""),"",BB3/(2*BA3)-1) | T3: =IF(OR(BB3="",BD3=""),"",BD3/(4*BB3)-1) | U3: =IF(OR(BC3="",BD3=""),"",INT(((BD3-BC3)/2)/60)&":"&TEXT(MOD((BD3-BC3)/2,60),"00.00")) | V3: =IF(BB3="","",ROUND(BB3,1)) | W3: =IF($A3="","",IFS(BB3="","Pas de T100 valide — Batterie A (T50 + T100).",AND(M3<>"",M3<=3),"Affutage (< 3 sem) — plus de test a fond. Allure de course.",AND(S3<>"",S3>0.1),"Vitesse OK, il casse sur 100 (lactique / pacing / technique).",AND(T3<>"",T3>0.12),"Manque aerobie / seuil — Batterie B (T200+T400) et series CSS.",AND(T3<>"",T3<0.06,S3<>"",S3<0.08),"Profil homogene — specificite d'allure vers la cible.",BA3="","Ajouter un T50 a la prochaine Batterie A.",TRUE,"Profil coherent. Voir consigne_charge pour deload / retest.")) | X3: =IF($A3="","",COUNTIFS(tblSeances[id_nageur],$A3,tblSeances[lundi],(TODAY()-WEEKDAY(TODAY(),3)),tblSeances[faite],"oui")&"/"&IFERROR(INDEX(tblNageurs[seances_sem],MATCH($A3,tblNageurs[id],0)),"")) | Y3: =IF($A3="","",SUMIFS(tblSeances[volume_m],tblSeances[id_nageur],$A3,tblSeances[lundi],(TODAY()-WEEKDAY(TODAY(),3)),tblSeances[faite],"oui")) | Z3: =IF($A3="","",TEXT(SUMIFS(tblSeances[volume_m],tblSeances[id_nageur],$A3,tblSeances[lundi],(TODAY()-WEEKDAY(TODAY(),3)),tblSeances[faite],"oui"),"0")&" / "&TEXT(SUMIFS(tblSeances[volume_m],tblSeances[id_nageur],$A3,tblSeances[lundi],(TODAY()-WEEKDAY(TODAY(),3))-7,tblSeances[faite],"oui"),"0")&" / "&TEXT(SUMIFS(tblSeances[volume_m],tblSeances[id_nageur],$A3,tblSeances[lundi],(TODAY()-WEEKDAY(TODAY(),3))-14,tblSeances[faite],"oui"),"0")) | AA3: =IF($A3="","",IFERROR(INDEX(FILTER(CHARGE!L$3:L$82,(CHARGE!A$3:A$82=$A3)*(CHARGE!B$3:B$82=(TODAY()-WEEKDAY(TODAY(),3)))),1),"")) | AB3: =IF($A3="","",IFERROR(INDEX(FILTER(CHARGE!M$3:M$82,(CHARGE!A$3:A$82=$A3)*(CHARGE!B$3:B$82=(TODAY()-WEEKDAY(TODAY(),3)))),1),"")) | AC3: =IF($A3="","",IFERROR(INDEX(FILTER(CHARGE!N$3:N$82,(CHARGE!A$3:A$82=$A3)*(CHARGE!B$3:B$82=(TODAY()-WEEKDAY(TODAY(),3)))),1),"")) | BA3: =IF($A3="","",IFERROR(INDEX(FILTER(tblTests[temps_sec],(tblTests[id_nageur]=$A3)*(tblTests[protocole]="T50")*(tblTests[nage]=$F3)*(tblTests[valide]="oui")*(tblTests[date]=MAXIFS(tblTests[date],tblTests[id_nageur],$A3,tblTests[protocole],"T50",tblTests[nage],$F3,tblTests[valide],"oui"))),1),"")) | BB3: =IF($A3="","",IFERROR(INDEX(FILTER(tblTests[temps_sec],(tblTests[id_nageur]=$A3)*(tblTests[protocole]="T100")*(tblTests[nage]=$F3)*(tblTests[valide]="oui")*(tblTests[date]=MAXIFS(tblTests[date],tblTests[id_nageur],$A3,tblTests[protocole],"T100",tblTests[nage],$F3,tblTests[valide],"oui"))),1),"")) | BC3: =IF($A3="","",IFERROR(INDEX(FILTER(tblTests[temps_sec],(tblTests[id_nageur]=$A3)*(tblTests[protocole]="T200")*(tblTests[nage]=$F3)*(tblTests[valide]="oui")*(tblTests[date]=MAXIFS(tblTests[date],tblTests[id_nageur],$A3,tblTests[protocole],"T200",tblTests[nage],$F3,tblTests[valide],"oui"))),1),"")) | BD3: =IF($A3="","",IFERROR(INDEX(FILTER(tblTests[temps_sec],(tblTests[id_nageur]=$A3)*(tblTests[protocole]="T400")*(tblTests[nage]=$F3)*(tblTests[valide]="oui")*(tblTests[date]=MAXIFS(tblTests[date],tblTests[id_nageur],$A3,tblTests[protocole],"T400",tblTests[nage],$F3,tblTests[valide],"oui"))),1),"")) | BE3: =IF($A3="","",IFERROR(INDEX(FILTER(tblTests[temps_sec],(tblTests[id_nageur]=$A3)*(tblTests[protocole]="T100")*(tblTests[nage]=$F3)*(tblTests[valide]="oui")*(tblTests[date]=IFERROR(LARGE(FILTER(tblTests[date],(tblTests[id_nageur]=$A3)*(tblTests[protocole]="T100")*(tblTests[nage]=$F3)*(tblTests[valide]="oui")),2),0))),1),"")) | BF3: =IF($A3="","",IFERROR(MAXIFS(tblTests[date],tblTests[id_nageur],$A3,tblTests[protocole],"T100",tblTests[nage],$F3,tblTests[valide],"oui"),""))
A4: =IFERROR(IF(INDEX(tblNageurs[id],2)="","",INDEX(tblNageurs[id],2)),"") | B4: =IF($A4="","",IFERROR(INDEX(tblNageurs[prenom],2),"")) | C4: =IF($A4="","",IFERROR(INDEX(tblNageurs[nom],2),"")) | D4: =IF($A4="","",IFERROR(INDEX(tblNageurs[niveau],2),"")) | E4: =IF($A4="","",IFERROR(INDEX(tblNageurs[statut],2),"")) | F4: =IF($A4="","",IF(OR($H4="dos",$H4="brasse",$H4="papillon"),$H4,"crawl")) | G4: =IF($A4="","",IFERROR(XLOOKUP($A4,tblObjectifs[cle_dashboard],tblObjectifs[discipline],""),"")) | H4: =IF($A4="","",IFERROR(XLOOKUP($A4,tblObjectifs[cle_dashboard],tblObjectifs[nage],""),"")) | I4: =IF($A4="","",IFERROR(XLOOKUP($A4,tblObjectifs[cle_dashboard],tblObjectifs[distance_m],""),"")) | J4: =IF($A4="","",IFERROR(XLOOKUP($A4,tblObjectifs[cle_dashboard],tblObjectifs[date_objectif],""),"")) | K4: =IF($A4="","",IFERROR(XLOOKUP($A4,tblObjectifs[cle_dashboard],tblObjectifs[lieu],""),"")) | L4: =IF($A4="","",IFERROR(XLOOKUP($A4,tblObjectifs[cle_dashboard],tblObjectifs[temps_cible],""),"")) | M4: =IF(OR($A4="",$J4=""),"",($J4-TODAY())/7) | N4: =IF(BA4="","",INT(BA4/60)&":"&TEXT(MOD(BA4,60),"00.00")) | O4: =IF(BB4="","",INT(BB4/60)&":"&TEXT(MOD(BB4,60),"00.00")) | P4: =IF(BC4="","",INT(BC4/60)&":"&TEXT(MOD(BC4,60),"00.00")) | Q4: =IF(BD4="","",INT(BD4/60)&":"&TEXT(MOD(BD4,60),"00.00")) | R4: =IF(OR(BB4="",BE4=""),"",(BB4-BE4)/BE4) | S4: =IF(OR(BA4="",BB4=""),"",BB4/(2*BA4)-1) | T4: =IF(OR(BB4="",BD4=""),"",BD4/(4*BB4)-1) | U4: =IF(OR(BC4="",BD4=""),"",INT(((BD4-BC4)/2)/60)&":"&TEXT(MOD((BD4-BC4)/2,60),"00.00")) | V4: =IF(BB4="","",ROUND(BB4,1)) | W4: =IF($A4="","",IFS(BB4="","Pas de T100 valide — Batterie A (T50 + T100).",AND(M4<>"",M4<=3),"Affutage (< 3 sem) — plus de test a fond. Allure de course.",AND(S4<>"",S4>0.1),"Vitesse OK, il casse sur 100 (lactique / pacing / technique).",AND(T4<>"",T4>0.12),"Manque aerobie / seuil — Batterie B (T200+T400) et series CSS.",AND(T4<>"",T4<0.06,S4<>"",S4<0.08),"Profil homogene — specificite d'allure vers la cible.",BA4="","Ajouter un T50 a la prochaine Batterie A.",TRUE,"Profil coherent. Voir consigne_charge pour deload / retest.")) | X4: =IF($A4="","",COUNTIFS(tblSeances[id_nageur],$A4,tblSeances[lundi],(TODAY()-WEEKDAY(TODAY(),3)),tblSeances[faite],"oui")&"/"&IFERROR(INDEX(tblNageurs[seances_sem],MATCH($A4,tblNageurs[id],0)),"")) | Y4: =IF($A4="","",SUMIFS(tblSeances[volume_m],tblSeances[id_nageur],$A4,tblSeances[lundi],(TODAY()-WEEKDAY(TODAY(),3)),tblSeances[faite],"oui")) | Z4: =IF($A4="","",TEXT(SUMIFS(tblSeances[volume_m],tblSeances[id_nageur],$A4,tblSeances[lundi],(TODAY()-WEEKDAY(TODAY(),3)),tblSeances[faite],"oui"),"0")&" / "&TEXT(SUMIFS(tblSeances[volume_m],tblSeances[id_nageur],$A4,tblSeances[lundi],(TODAY()-WEEKDAY(TODAY(),3))-7,tblSeances[faite],"oui"),"0")&" / "&TEXT(SUMIFS(tblSeances[volume_m],tblSeances[id_nageur],$A4,tblSeances[lundi],(TODAY()-WEEKDAY(TODAY(),3))-14,tblSeances[faite],"oui"),"0")) | AA4: =IF($A4="","",IFERROR(INDEX(FILTER(CHARGE!L$3:L$82,(CHARGE!A$3:A$82=$A4)*(CHARGE!B$3:B$82=(TODAY()-WEEKDAY(TODAY(),3)))),1),"")) | AB4: =IF($A4="","",IFERROR(INDEX(FILTER(CHARGE!M$3:M$82,(CHARGE!A$3:A$82=$A4)*(CHARGE!B$3:B$82=(TODAY()-WEEKDAY(TODAY(),3)))),1),"")) | AC4: =IF($A4="","",IFERROR(INDEX(FILTER(CHARGE!N$3:N$82,(CHARGE!A$3:A$82=$A4)*(CHARGE!B$3:B$82=(TODAY()-WEEKDAY(TODAY(),3)))),1),"")) | BA4: =IF($A4="","",IFERROR(INDEX(FILTER(tblTests[temps_sec],(tblTests[id_nageur]=$A4)*(tblTests[protocole]="T50")*(tblTests[nage]=$F4)*(tblTests[valide]="oui")*(tblTests[date]=MAXIFS(tblTests[date],tblTests[id_nageur],$A4,tblTests[protocole],"T50",tblTests[nage],$F4,tblTests[valide],"oui"))),1),"")) | BB4: =IF($A4="","",IFERROR(INDEX(FILTER(tblTests[temps_sec],(tblTests[id_nageur]=$A4)*(tblTests[protocole]="T100")*(tblTests[nage]=$F4)*(tblTests[valide]="oui")*(tblTests[date]=MAXIFS(tblTests[date],tblTests[id_nageur],$A4,tblTests[protocole],"T100",tblTests[nage],$F4,tblTests[valide],"oui"))),1),"")) | BC4: =IF($A4="","",IFERROR(INDEX(FILTER(tblTests[temps_sec],(tblTests[id_nageur]=$A4)*(tblTests[protocole]="T200")*(tblTests[nage]=$F4)*(tblTests[valide]="oui")*(tblTests[date]=MAXIFS(tblTests[date],tblTests[id_nageur],$A4,tblTests[protocole],"T200",tblTests[nage],$F4,tblTests[valide],"oui"))),1),"")) | BD4: =IF($A4="","",IFERROR(INDEX(FILTER(tblTests[temps_sec],(tblTests[id_nageur]=$A4)*(tblTests[protocole]="T400")*(tblTests[nage]=$F4)*(tblTests[valide]="oui")*(tblTests[date]=MAXIFS(tblTests[date],tblTests[id_nageur],$A4,tblTests[protocole],"T400",tblTests[nage],$F4,tblTests[valide],"oui"))),1),"")) | BE4: =IF($A4="","",IFERROR(INDEX(FILTER(tblTests[temps_sec],(tblTests[id_nageur]=$A4)*(tblTests[protocole]="T100")*(tblTests[nage]=$F4)*(tblTests[valide]="oui")*(tblTests[date]=IFERROR(LARGE(FILTER(tblTests[date],(tblTests[id_nageur]=$A4)*(tblTests[protocole]="T100")*(tblTests[nage]=$F4)*(tblTests[valide]="oui")),2),0))),1),"")) | BF4: =IF($A4="","",IFERROR(MAXIFS(tblTests[date],tblTests[id_nageur],$A4,tblTests[protocole],"T100",tblTests[nage],$F4,tblTests[valide],"oui"),""))
A5: =IFERROR(IF(INDEX(tblNageurs[id],3)="","",INDEX(tblNageurs[id],3)),"") | B5: =IF($A5="","",IFERROR(INDEX(tblNageurs[prenom],3),"")) | C5: =IF($A5="","",IFERROR(INDEX(tblNageurs[nom],3),"")) | D5: =IF($A5="","",IFERROR(INDEX(tblNageurs[niveau],3),"")) | E5: =IF($A5="","",IFERROR(INDEX(tblNageurs[statut],3),"")) | F5: =IF($A5="","",IF(OR($H5="dos",$H5="brasse",$H5="papillon"),$H5,"crawl")) | G5: =IF($A5="","",IFERROR(XLOOKUP($A5,tblObjectifs[cle_dashboard],tblObjectifs[discipline],""),"")) | H5: =IF($A5="","",IFERROR(XLOOKUP($A5,tblObjectifs[cle_dashboard],tblObjectifs[nage],""),"")) | I5: =IF($A5="","",IFERROR(XLOOKUP($A5,tblObjectifs[cle_dashboard],tblObjectifs[distance_m],""),"")) | J5: =IF($A5="","",IFERROR(XLOOKUP($A5,tblObjectifs[cle_dashboard],tblObjectifs[date_objectif],""),"")) | K5: =IF($A5="","",IFERROR(XLOOKUP($A5,tblObjectifs[cle_dashboard],tblObjectifs[lieu],""),"")) | L5: =IF($A5="","",IFERROR(XLOOKUP($A5,tblObjectifs[cle_dashboard],tblObjectifs[temps_cible],""),"")) | M5: =IF(OR($A5="",$J5=""),"",($J5-TODAY())/7) | N5: =IF(BA5="","",INT(BA5/60)&":"&TEXT(MOD(BA5,60),"00.00")) | O5: =IF(BB5="","",INT(BB5/60)&":"&TEXT(MOD(BB5,60),"00.00")) | P5: =IF(BC5="","",INT(BC5/60)&":"&TEXT(MOD(BC5,60),"00.00")) | Q5: =IF(BD5="","",INT(BD5/60)&":"&TEXT(MOD(BD5,60),"00.00")) | R5: =IF(OR(BB5="",BE5=""),"",(BB5-BE5)/BE5) | S5: =IF(OR(BA5="",BB5=""),"",BB5/(2*BA5)-1) | T5: =IF(OR(BB5="",BD5=""),"",BD5/(4*BB5)-1) | U5: =IF(OR(BC5="",BD5=""),"",INT(((BD5-BC5)/2)/60)&":"&TEXT(MOD((BD5-BC5)/2,60),"00.00")) | V5: =IF(BB5="","",ROUND(BB5,1)) | W5: =IF($A5="","",IFS(BB5="","Pas de T100 valide — Batterie A (T50 + T100).",AND(M5<>"",M5<=3),"Affutage (< 3 sem) — plus de test a fond. Allure de course.",AND(S5<>"",S5>0.1),"Vitesse OK, il casse sur 100 (lactique / pacing / technique).",AND(T5<>"",T5>0.12),"Manque aerobie / seuil — Batterie B (T200+T400) et series CSS.",AND(T5<>"",T5<0.06,S5<>"",S5<0.08),"Profil homogene — specificite d'allure vers la cible.",BA5="","Ajouter un T50 a la prochaine Batterie A.",TRUE,"Profil coherent. Voir consigne_charge pour deload / retest.")) | X5: =IF($A5="","",COUNTIFS(tblSeances[id_nageur],$A5,tblSeances[lundi],(TODAY()-WEEKDAY(TODAY(),3)),tblSeances[faite],"oui")&"/"&IFERROR(INDEX(tblNageurs[seances_sem],MATCH($A5,tblNageurs[id],0)),"")) | Y5: =IF($A5="","",SUMIFS(tblSeances[volume_m],tblSeances[id_nageur],$A5,tblSeances[lundi],(TODAY()-WEEKDAY(TODAY(),3)),tblSeances[faite],"oui")) | Z5: =IF($A5="","",TEXT(SUMIFS(tblSeances[volume_m],tblSeances[id_nageur],$A5,tblSeances[lundi],(TODAY()-WEEKDAY(TODAY(),3)),tblSeances[faite],"oui"),"0")&" / "&TEXT(SUMIFS(tblSeances[volume_m],tblSeances[id_nageur],$A5,tblSeances[lundi],(TODAY()-WEEKDAY(TODAY(),3))-7,tblSeances[faite],"oui"),"0")&" / "&TEXT(SUMIFS(tblSeances[volume_m],tblSeances[id_nageur],$A5,tblSeances[lundi],(TODAY()-WEEKDAY(TODAY(),3))-14,tblSeances[faite],"oui"),"0")) | AA5: =IF($A5="","",IFERROR(INDEX(FILTER(CHARGE!L$3:L$82,(CHARGE!A$3:A$82=$A5)*(CHARGE!B$3:B$82=(TODAY()-WEEKDAY(TODAY(),3)))),1),"")) | AB5: =IF($A5="","",IFERROR(INDEX(FILTER(CHARGE!M$3:M$82,(CHARGE!A$3:A$82=$A5)*(CHARGE!B$3:B$82=(TODAY()-WEEKDAY(TODAY(),3)))),1),"")) | AC5: =IF($A5="","",IFERROR(INDEX(FILTER(CHARGE!N$3:N$82,(CHARGE!A$3:A$82=$A5)*(CHARGE!B$3:B$82=(TODAY()-WEEKDAY(TODAY(),3)))),1),"")) | BA5: =IF($A5="","",IFERROR(INDEX(FILTER(tblTests[temps_sec],(tblTests[id_nageur]=$A5)*(tblTests[protocole]="T50")*(tblTests[nage]=$F5)*(tblTests[valide]="oui")*(tblTests[date]=MAXIFS(tblTests[date],tblTests[id_nageur],$A5,tblTests[protocole],"T50",tblTests[nage],$F5,tblTests[valide],"oui"))),1),"")) | BB5: =IF($A5="","",IFERROR(INDEX(FILTER(tblTests[temps_sec],(tblTests[id_nageur]=$A5)*(tblTests[protocole]="T100")*(tblTests[nage]=$F5)*(tblTests[valide]="oui")*(tblTests[date]=MAXIFS(tblTests[date],tblTests[id_nageur],$A5,tblTests[protocole],"T100",tblTests[nage],$F5,tblTests[valide],"oui"))),1),"")) | BC5: =IF($A5="","",IFERROR(INDEX(FILTER(tblTests[temps_sec],(tblTests[id_nageur]=$A5)*(tblTests[protocole]="T200")*(tblTests[nage]=$F5)*(tblTests[valide]="oui")*(tblTests[date]=MAXIFS(tblTests[date],tblTests[id_nageur],$A5,tblTests[protocole],"T200",tblTests[nage],$F5,tblTests[valide],"oui"))),1),"")) | BD5: =IF($A5="","",IFERROR(INDEX(FILTER(tblTests[temps_sec],(tblTests[id_nageur]=$A5)*(tblTests[protocole]="T400")*(tblTests[nage]=$F5)*(tblTests[valide]="oui")*(tblTests[date]=MAXIFS(tblTests[date],tblTests[id_nageur],$A5,tblTests[protocole],"T400",tblTests[nage],$F5,tblTests[valide],"oui"))),1),"")) | BE5: =IF($A5="","",IFERROR(INDEX(FILTER(tblTests[temps_sec],(tblTests[id_nageur]=$A5)*(tblTests[protocole]="T100")*(tblTests[nage]=$F5)*(tblTests[valide]="oui")*(tblTests[date]=IFERROR(LARGE(FILTER(tblTests[date],(tblTests[id_nageur]=$A5)*(tblTests[protocole]="T100")*(tblTests[nage]=$F5)*(tblTests[valide]="oui")),2),0))),1),"")) | BF5: =IF($A5="","",IFERROR(MAXIFS(tblTests[date],tblTests[id_nageur],$A5,tblTests[protocole],"T100",tblTests[nage],$F5,tblTests[valide],"oui"),""))
A6: =IFERROR(IF(INDEX(tblNageurs[id],4)="","",INDEX(tblNageurs[id],4)),"") | B6: =IF($A6="","",IFERROR(INDEX(tblNageurs[prenom],4),"")) | C6: =IF($A6="","",IFERROR(INDEX(tblNageurs[nom],4),"")) | D6: =IF($A6="","",IFERROR(INDEX(tblNageurs[niveau],4),"")) | E6: =IF($A6="","",IFERROR(INDEX(tblNageurs[statut],4),"")) | F6: =IF($A6="","",IF(OR($H6="dos",$H6="brasse",$H6="papillon"),$H6,"crawl")) | G6: =IF($A6="","",IFERROR(XLOOKUP($A6,tblObjectifs[cle_dashboard],tblObjectifs[discipline],""),"")) | H6: =IF($A6="","",IFERROR(XLOOKUP($A6,tblObjectifs[cle_dashboard],tblObjectifs[nage],""),"")) | I6: =IF($A6="","",IFERROR(XLOOKUP($A6,tblObjectifs[cle_dashboard],tblObjectifs[distance_m],""),"")) | J6: =IF($A6="","",IFERROR(XLOOKUP($A6,tblObjectifs[cle_dashboard],tblObjectifs[date_objectif],""),"")) | K6: =IF($A6="","",IFERROR(XLOOKUP($A6,tblObjectifs[cle_dashboard],tblObjectifs[lieu],""),"")) | L6: =IF($A6="","",IFERROR(XLOOKUP($A6,tblObjectifs[cle_dashboard],tblObjectifs[temps_cible],""),"")) | M6: =IF(OR($A6="",$J6=""),"",($J6-TODAY())/7) | N6: =IF(BA6="","",INT(BA6/60)&":"&TEXT(MOD(BA6,60),"00.00")) | O6: =IF(BB6="","",INT(BB6/60)&":"&TEXT(MOD(BB6,60),"00.00")) | P6: =IF(BC6="","",INT(BC6/60)&":"&TEXT(MOD(BC6,60),"00.00")) | Q6: =IF(BD6="","",INT(BD6/60)&":"&TEXT(MOD(BD6,60),"00.00")) | R6: =IF(OR(BB6="",BE6=""),"",(BB6-BE6)/BE6) | S6: =IF(OR(BA6="",BB6=""),"",BB6/(2*BA6)-1) | T6: =IF(OR(BB6="",BD6=""),"",BD6/(4*BB6)-1) | U6: =IF(OR(BC6="",BD6=""),"",INT(((BD6-BC6)/2)/60)&":"&TEXT(MOD((BD6-BC6)/2,60),"00.00")) | V6: =IF(BB6="","",ROUND(BB6,1)) | W6: =IF($A6="","",IFS(BB6="","Pas de T100 valide — Batterie A (T50 + T100).",AND(M6<>"",M6<=3),"Affutage (< 3 sem) — plus de test a fond. Allure de course.",AND(S6<>"",S6>0.1),"Vitesse OK, il casse sur 100 (lactique / pacing / technique).",AND(T6<>"",T6>0.12),"Manque aerobie / seuil — Batterie B (T200+T400) et series CSS.",AND(T6<>"",T6<0.06,S6<>"",S6<0.08),"Profil homogene — specificite d'allure vers la cible.",BA6="","Ajouter un T50 a la prochaine Batterie A.",TRUE,"Profil coherent. Voir consigne_charge pour deload / retest.")) | X6: =IF($A6="","",COUNTIFS(tblSeances[id_nageur],$A6,tblSeances[lundi],(TODAY()-WEEKDAY(TODAY(),3)),tblSeances[faite],"oui")&"/"&IFERROR(INDEX(tblNageurs[seances_sem],MATCH($A6,tblNageurs[id],0)),"")) | Y6: =IF($A6="","",SUMIFS(tblSeances[volume_m],tblSeances[id_nageur],$A6,tblSeances[lundi],(TODAY()-WEEKDAY(TODAY(),3)),tblSeances[faite],"oui")) | Z6: =IF($A6="","",TEXT(SUMIFS(tblSeances[volume_m],tblSeances[id_nageur],$A6,tblSeances[lundi],(TODAY()-WEEKDAY(TODAY(),3)),tblSeances[faite],"oui"),"0")&" / "&TEXT(SUMIFS(tblSeances[volume_m],tblSeances[id_nageur],$A6,tblSeances[lundi],(TODAY()-WEEKDAY(TODAY(),3))-7,tblSeances[faite],"oui"),"0")&" / "&TEXT(SUMIFS(tblSeances[volume_m],tblSeances[id_nageur],$A6,tblSeances[lundi],(TODAY()-WEEKDAY(TODAY(),3))-14,tblSeances[faite],"oui"),"0")) | AA6: =IF($A6="","",IFERROR(INDEX(FILTER(CHARGE!L$3:L$82,(CHARGE!A$3:A$82=$A6)*(CHARGE!B$3:B$82=(TODAY()-WEEKDAY(TODAY(),3)))),1),"")) | AB6: =IF($A6="","",IFERROR(INDEX(FILTER(CHARGE!M$3:M$82,(CHARGE!A$3:A$82=$A6)*(CHARGE!B$3:B$82=(TODAY()-WEEKDAY(TODAY(),3)))),1),"")) | AC6: =IF($A6="","",IFERROR(INDEX(FILTER(CHARGE!N$3:N$82,(CHARGE!A$3:A$82=$A6)*(CHARGE!B$3:B$82=(TODAY()-WEEKDAY(TODAY(),3)))),1),"")) | BA6: =IF($A6="","",IFERROR(INDEX(FILTER(tblTests[temps_sec],(tblTests[id_nageur]=$A6)*(tblTests[protocole]="T50")*(tblTests[nage]=$F6)*(tblTests[valide]="oui")*(tblTests[date]=MAXIFS(tblTests[date],tblTests[id_nageur],$A6,tblTests[protocole],"T50",tblTests[nage],$F6,tblTests[valide],"oui"))),1),"")) | BB6: =IF($A6="","",IFERROR(INDEX(FILTER(tblTests[temps_sec],(tblTests[id_nageur]=$A6)*(tblTests[protocole]="T100")*(tblTests[nage]=$F6)*(tblTests[valide]="oui")*(tblTests[date]=MAXIFS(tblTests[date],tblTests[id_nageur],$A6,tblTests[protocole],"T100",tblTests[nage],$F6,tblTests[valide],"oui"))),1),"")) | BC6: =IF($A6="","",IFERROR(INDEX(FILTER(tblTests[temps_sec],(tblTests[id_nageur]=$A6)*(tblTests[protocole]="T200")*(tblTests[nage]=$F6)*(tblTests[valide]="oui")*(tblTests[date]=MAXIFS(tblTests[date],tblTests[id_nageur],$A6,tblTests[protocole],"T200",tblTests[nage],$F6,tblTests[valide],"oui"))),1),"")) | BD6: =IF($A6="","",IFERROR(INDEX(FILTER(tblTests[temps_sec],(tblTests[id_nageur]=$A6)*(tblTests[protocole]="T400")*(tblTests[nage]=$F6)*(tblTests[valide]="oui")*(tblTests[date]=MAXIFS(tblTests[date],tblTests[id_nageur],$A6,tblTests[protocole],"T400",tblTests[nage],$F6,tblTests[valide],"oui"))),1),"")) | BE6: =IF($A6="","",IFERROR(INDEX(FILTER(tblTests[temps_sec],(tblTests[id_nageur]=$A6)*(tblTests[protocole]="T100")*(tblTests[nage]=$F6)*(tblTests[valide]="oui")*(tblTests[date]=IFERROR(LARGE(FILTER(tblTests[date],(tblTests[id_nageur]=$A6)*(tblTests[protocole]="T100")*(tblTests[nage]=$F6)*(tblTests[valide]="oui")),2),0))),1),"")) | BF6: =IF($A6="","",IFERROR(MAXIFS(tblTests[date],tblTests[id_nageur],$A6,tblTests[protocole],"T100",tblTests[nage],$F6,tblTests[valide],"oui"),""))
A7: =IFERROR(IF(INDEX(tblNageurs[id],5)="","",INDEX(tblNageurs[id],5)),"") | B7: =IF($A7="","",IFERROR(INDEX(tblNageurs[prenom],5),"")) | C7: =IF($A7="","",IFERROR(INDEX(tblNageurs[nom],5),"")) | D7: =IF($A7="","",IFERROR(INDEX(tblNageurs[niveau],5),"")) | E7: =IF($A7="","",IFERROR(INDEX(tblNageurs[statut],5),"")) | F7: =IF($A7="","",IF(OR($H7="dos",$H7="brasse",$H7="papillon"),$H7,"crawl")) | G7: =IF($A7="","",IFERROR(XLOOKUP($A7,tblObjectifs[cle_dashboard],tblObjectifs[discipline],""),"")) | H7: =IF($A7="","",IFERROR(XLOOKUP($A7,tblObjectifs[cle_dashboard],tblObjectifs[nage],""),"")) | I7: =IF($A7="","",IFERROR(XLOOKUP($A7,tblObjectifs[cle_dashboard],tblObjectifs[distance_m],""),"")) | J7: =IF($A7="","",IFERROR(XLOOKUP($A7,tblObjectifs[cle_dashboard],tblObjectifs[date_objectif],""),"")) | K7: =IF($A7="","",IFERROR(XLOOKUP($A7,tblObjectifs[cle_dashboard],tblObjectifs[lieu],""),"")) | L7: =IF($A7="","",IFERROR(XLOOKUP($A7,tblObjectifs[cle_dashboard],tblObjectifs[temps_cible],""),"")) | M7: =IF(OR($A7="",$J7=""),"",($J7-TODAY())/7) | N7: =IF(BA7="","",INT(BA7/60)&":"&TEXT(MOD(BA7,60),"00.00")) | O7: =IF(BB7="","",INT(BB7/60)&":"&TEXT(MOD(BB7,60),"00.00")) | P7: =IF(BC7="","",INT(BC7/60)&":"&TEXT(MOD(BC7,60),"00.00")) | Q7: =IF(BD7="","",INT(BD7/60)&":"&TEXT(MOD(BD7,60),"00.00")) | R7: =IF(OR(BB7="",BE7=""),"",(BB7-BE7)/BE7) | S7: =IF(OR(BA7="",BB7=""),"",BB7/(2*BA7)-1) | T7: =IF(OR(BB7="",BD7=""),"",BD7/(4*BB7)-1) | U7: =IF(OR(BC7="",BD7=""),"",INT(((BD7-BC7)/2)/60)&":"&TEXT(MOD((BD7-BC7)/2,60),"00.00")) | V7: =IF(BB7="","",ROUND(BB7,1)) | W7: =IF($A7="","",IFS(BB7="","Pas de T100 valide — Batterie A (T50 + T100).",AND(M7<>"",M7<=3),"Affutage (< 3 sem) — plus de test a fond. Allure de course.",AND(S7<>"",S7>0.1),"Vitesse OK, il casse sur 100 (lactique / pacing / technique).",AND(T7<>"",T7>0.12),"Manque aerobie / seuil — Batterie B (T200+T400) et series CSS.",AND(T7<>"",T7<0.06,S7<>"",S7<0.08),"Profil homogene — specificite d'allure vers la cible.",BA7="","Ajouter un T50 a la prochaine Batterie A.",TRUE,"Profil coherent. Voir consigne_charge pour deload / retest.")) | X7: =IF($A7="","",COUNTIFS(tblSeances[id_nageur],$A7,tblSeances[lundi],(TODAY()-WEEKDAY(TODAY(),3)),tblSeances[faite],"oui")&"/"&IFERROR(INDEX(tblNageurs[seances_sem],MATCH($A7,tblNageurs[id],0)),"")) | Y7: =IF($A7="","",SUMIFS(tblSeances[volume_m],tblSeances[id_nageur],$A7,tblSeances[lundi],(TODAY()-WEEKDAY(TODAY(),3)),tblSeances[faite],"oui")) | Z7: =IF($A7="","",TEXT(SUMIFS(tblSeances[volume_m],tblSeances[id_nageur],$A7,tblSeances[lundi],(TODAY()-WEEKDAY(TODAY(),3)),tblSeances[faite],"oui"),"0")&" / "&TEXT(SUMIFS(tblSeances[volume_m],tblSeances[id_nageur],$A7,tblSeances[lundi],(TODAY()-WEEKDAY(TODAY(),3))-7,tblSeances[faite],"oui"),"0")&" / "&TEXT(SUMIFS(tblSeances[volume_m],tblSeances[id_nageur],$A7,tblSeances[lundi],(TODAY()-WEEKDAY(TODAY(),3))-14,tblSeances[faite],"oui"),"0")) | AA7: =IF($A7="","",IFERROR(INDEX(FILTER(CHARGE!L$3:L$82,(CHARGE!A$3:A$82=$A7)*(CHARGE!B$3:B$82=(TODAY()-WEEKDAY(TODAY(),3)))),1),"")) | AB7: =IF($A7="","",IFERROR(INDEX(FILTER(CHARGE!M$3:M$82,(CHARGE!A$3:A$82=$A7)*(CHARGE!B$3:B$82=(TODAY()-WEEKDAY(TODAY(),3)))),1),"")) | AC7: =IF($A7="","",IFERROR(INDEX(FILTER(CHARGE!N$3:N$82,(CHARGE!A$3:A$82=$A7)*(CHARGE!B$3:B$82=(TODAY()-WEEKDAY(TODAY(),3)))),1),"")) | BA7: =IF($A7="","",IFERROR(INDEX(FILTER(tblTests[temps_sec],(tblTests[id_nageur]=$A7)*(tblTests[protocole]="T50")*(tblTests[nage]=$F7)*(tblTests[valide]="oui")*(tblTests[date]=MAXIFS(tblTests[date],tblTests[id_nageur],$A7,tblTests[protocole],"T50",tblTests[nage],$F7,tblTests[valide],"oui"))),1),"")) | BB7: =IF($A7="","",IFERROR(INDEX(FILTER(tblTests[temps_sec],(tblTests[id_nageur]=$A7)*(tblTests[protocole]="T100")*(tblTests[nage]=$F7)*(tblTests[valide]="oui")*(tblTests[date]=MAXIFS(tblTests[date],tblTests[id_nageur],$A7,tblTests[protocole],"T100",tblTests[nage],$F7,tblTests[valide],"oui"))),1),"")) | BC7: =IF($A7="","",IFERROR(INDEX(FILTER(tblTests[temps_sec],(tblTests[id_nageur]=$A7)*(tblTests[protocole]="T200")*(tblTests[nage]=$F7)*(tblTests[valide]="oui")*(tblTests[date]=MAXIFS(tblTests[date],tblTests[id_nageur],$A7,tblTests[protocole],"T200",tblTests[nage],$F7,tblTests[valide],"oui"))),1),"")) | BD7: =IF($A7="","",IFERROR(INDEX(FILTER(tblTests[temps_sec],(tblTests[id_nageur]=$A7)*(tblTests[protocole]="T400")*(tblTests[nage]=$F7)*(tblTests[valide]="oui")*(tblTests[date]=MAXIFS(tblTests[date],tblTests[id_nageur],$A7,tblTests[protocole],"T400",tblTests[nage],$F7,tblTests[valide],"oui"))),1),"")) | BE7: =IF($A7="","",IFERROR(INDEX(FILTER(tblTests[temps_sec],(tblTests[id_nageur]=$A7)*(tblTests[protocole]="T100")*(tblTests[nage]=$F7)*(tblTests[valide]="oui")*(tblTests[date]=IFERROR(LARGE(FILTER(tblTests[date],(tblTests[id_nageur]=$A7)*(tblTests[protocole]="T100")*(tblTests[nage]=$F7)*(tblTests[valide]="oui")),2),0))),1),"")) | BF7: =IF($A7="","",IFERROR(MAXIFS(tblTests[date],tblTests[id_nageur],$A7,tblTests[protocole],"T100",tblTests[nage],$F7,tblTests[valide],"oui"),""))
A8: =IFERROR(IF(INDEX(tblNageurs[id],6)="","",INDEX(tblNageurs[id],6)),"") | B8: =IF($A8="","",IFERROR(INDEX(tblNageurs[prenom],6),"")) | C8: =IF($A8="","",IFERROR(INDEX(tblNageurs[nom],6),"")) | D8: =IF($A8="","",IFERROR(INDEX(tblNageurs[niveau],6),"")) | E8: =IF($A8="","",IFERROR(INDEX(tblNageurs[statut],6),"")) | F8: =IF($A8="","",IF(OR($H8="dos",$H8="brasse",$H8="papillon"),$H8,"crawl")) | G8: =IF($A8="","",IFERROR(XLOOKUP($A8,tblObjectifs[cle_dashboard],tblObjectifs[discipline],""),"")) | H8: =IF($A8="","",IFERROR(XLOOKUP($A8,tblObjectifs[cle_dashboard],tblObjectifs[nage],""),"")) | I8: =IF($A8="","",IFERROR(XLOOKUP($A8,tblObjectifs[cle_dashboard],tblObjectifs[distance_m],""),"")) | J8: =IF($A8="","",IFERROR(XLOOKUP($A8,tblObjectifs[cle_dashboard],tblObjectifs[date_objectif],""),"")) | K8: =IF($A8="","",IFERROR(XLOOKUP($A8,tblObjectifs[cle_dashboard],tblObjectifs[lieu],""),"")) | L8: =IF($A8="","",IFERROR(XLOOKUP($A8,tblObjectifs[cle_dashboard],tblObjectifs[temps_cible],""),"")) | M8: =IF(OR($A8="",$J8=""),"",($J8-TODAY())/7) | N8: =IF(BA8="","",INT(BA8/60)&":"&TEXT(MOD(BA8,60),"00.00")) | O8: =IF(BB8="","",INT(BB8/60)&":"&TEXT(MOD(BB8,60),"00.00")) | P8: =IF(BC8="","",INT(BC8/60)&":"&TEXT(MOD(BC8,60),"00.00")) | Q8: =IF(BD8="","",INT(BD8/60)&":"&TEXT(MOD(BD8,60),"00.00")) | R8: =IF(OR(BB8="",BE8=""),"",(BB8-BE8)/BE8) | S8: =IF(OR(BA8="",BB8=""),"",BB8/(2*BA8)-1) | T8: =IF(OR(BB8="",BD8=""),"",BD8/(4*BB8)-1) | U8: =IF(OR(BC8="",BD8=""),"",INT(((BD8-BC8)/2)/60)&":"&TEXT(MOD((BD8-BC8)/2,60),"00.00")) | V8: =IF(BB8="","",ROUND(BB8,1)) | W8: =IF($A8="","",IFS(BB8="","Pas de T100 valide — Batterie A (T50 + T100).",AND(M8<>"",M8<=3),"Affutage (< 3 sem) — plus de test a fond. Allure de course.",AND(S8<>"",S8>0.1),"Vitesse OK, il casse sur 100 (lactique / pacing / technique).",AND(T8<>"",T8>0.12),"Manque aerobie / seuil — Batterie B (T200+T400) et series CSS.",AND(T8<>"",T8<0.06,S8<>"",S8<0.08),"Profil homogene — specificite d'allure vers la cible.",BA8="","Ajouter un T50 a la prochaine Batterie A.",TRUE,"Profil coherent. Voir consigne_charge pour deload / retest.")) | X8: =IF($A8="","",COUNTIFS(tblSeances[id_nageur],$A8,tblSeances[lundi],(TODAY()-WEEKDAY(TODAY(),3)),tblSeances[faite],"oui")&"/"&IFERROR(INDEX(tblNageurs[seances_sem],MATCH($A8,tblNageurs[id],0)),"")) | Y8: =IF($A8="","",SUMIFS(tblSeances[volume_m],tblSeances[id_nageur],$A8,tblSeances[lundi],(TODAY()-WEEKDAY(TODAY(),3)),tblSeances[faite],"oui")) | Z8: =IF($A8="","",TEXT(SUMIFS(tblSeances[volume_m],tblSeances[id_nageur],$A8,tblSeances[lundi],(TODAY()-WEEKDAY(TODAY(),3)),tblSeances[faite],"oui"),"0")&" / "&TEXT(SUMIFS(tblSeances[volume_m],tblSeances[id_nageur],$A8,tblSeances[lundi],(TODAY()-WEEKDAY(TODAY(),3))-7,tblSeances[faite],"oui"),"0")&" / "&TEXT(SUMIFS(tblSeances[volume_m],tblSeances[id_nageur],$A8,tblSeances[lundi],(TODAY()-WEEKDAY(TODAY(),3))-14,tblSeances[faite],"oui"),"0")) | AA8: =IF($A8="","",IFERROR(INDEX(FILTER(CHARGE!L$3:L$82,(CHARGE!A$3:A$82=$A8)*(CHARGE!B$3:B$82=(TODAY()-WEEKDAY(TODAY(),3)))),1),"")) | AB8: =IF($A8="","",IFERROR(INDEX(FILTER(CHARGE!M$3:M$82,(CHARGE!A$3:A$82=$A8)*(CHARGE!B$3:B$82=(TODAY()-WEEKDAY(TODAY(),3)))),1),"")) | AC8: =IF($A8="","",IFERROR(INDEX(FILTER(CHARGE!N$3:N$82,(CHARGE!A$3:A$82=$A8)*(CHARGE!B$3:B$82=(TODAY()-WEEKDAY(TODAY(),3)))),1),"")) | BA8: =IF($A8="","",IFERROR(INDEX(FILTER(tblTests[temps_sec],(tblTests[id_nageur]=$A8)*(tblTests[protocole]="T50")*(tblTests[nage]=$F8)*(tblTests[valide]="oui")*(tblTests[date]=MAXIFS(tblTests[date],tblTests[id_nageur],$A8,tblTests[protocole],"T50",tblTests[nage],$F8,tblTests[valide],"oui"))),1),"")) | BB8: =IF($A8="","",IFERROR(INDEX(FILTER(tblTests[temps_sec],(tblTests[id_nageur]=$A8)*(tblTests[protocole]="T100")*(tblTests[nage]=$F8)*(tblTests[valide]="oui")*(tblTests[date]=MAXIFS(tblTests[date],tblTests[id_nageur],$A8,tblTests[protocole],"T100",tblTests[nage],$F8,tblTests[valide],"oui"))),1),"")) | BC8: =IF($A8="","",IFERROR(INDEX(FILTER(tblTests[temps_sec],(tblTests[id_nageur]=$A8)*(tblTests[protocole]="T200")*(tblTests[nage]=$F8)*(tblTests[valide]="oui")*(tblTests[date]=MAXIFS(tblTests[date],tblTests[id_nageur],$A8,tblTests[protocole],"T200",tblTests[nage],$F8,tblTests[valide],"oui"))),1),"")) | BD8: =IF($A8="","",IFERROR(INDEX(FILTER(tblTests[temps_sec],(tblTests[id_nageur]=$A8)*(tblTests[protocole]="T400")*(tblTests[nage]=$F8)*(tblTests[valide]="oui")*(tblTests[date]=MAXIFS(tblTests[date],tblTests[id_nageur],$A8,tblTests[protocole],"T400",tblTests[nage],$F8,tblTests[valide],"oui"))),1),"")) | BE8: =IF($A8="","",IFERROR(INDEX(FILTER(tblTests[temps_sec],(tblTests[id_nageur]=$A8)*(tblTests[protocole]="T100")*(tblTests[nage]=$F8)*(tblTests[valide]="oui")*(tblTests[date]=IFERROR(LARGE(FILTER(tblTests[date],(tblTests[id_nageur]=$A8)*(tblTests[protocole]="T100")*(tblTests[nage]=$F8)*(tblTests[valide]="oui")),2),0))),1),"")) | BF8: =IF($A8="","",IFERROR(MAXIFS(tblTests[date],tblTests[id_nageur],$A8,tblTests[protocole],"T100",tblTests[nage],$F8,tblTests[valide],"oui"),""))
A9: =IFERROR(IF(INDEX(tblNageurs[id],7)="","",INDEX(tblNageurs[id],7)),"") | B9: =IF($A9="","",IFERROR(INDEX(tblNageurs[prenom],7),"")) | C9: =IF($A9="","",IFERROR(INDEX(tblNageurs[nom],7),"")) | D9: =IF($A9="","",IFERROR(INDEX(tblNageurs[niveau],7),"")) | E9: =IF($A9="","",IFERROR(INDEX(tblNageurs[statut],7),"")) | F9: =IF($A9="","",IF(OR($H9="dos",$H9="brasse",$H9="papillon"),$H9,"crawl")) | G9: =IF($A9="","",IFERROR(XLOOKUP($A9,tblObjectifs[cle_dashboard],tblObjectifs[discipline],""),"")) | H9: =IF($A9="","",IFERROR(XLOOKUP($A9,tblObjectifs[cle_dashboard],tblObjectifs[nage],""),"")) | I9: =IF($A9="","",IFERROR(XLOOKUP($A9,tblObjectifs[cle_dashboard],tblObjectifs[distance_m],""),"")) | J9: =IF($A9="","",IFERROR(XLOOKUP($A9,tblObjectifs[cle_dashboard],tblObjectifs[date_objectif],""),"")) | K9: =IF($A9="","",IFERROR(XLOOKUP($A9,tblObjectifs[cle_dashboard],tblObjectifs[lieu],""),"")) | L9: =IF($A9="","",IFERROR(XLOOKUP($A9,tblObjectifs[cle_dashboard],tblObjectifs[temps_cible],""),"")) | M9: =IF(OR($A9="",$J9=""),"",($J9-TODAY())/7) | N9: =IF(BA9="","",INT(BA9/60)&":"&TEXT(MOD(BA9,60),"00.00")) | O9: =IF(BB9="","",INT(BB9/60)&":"&TEXT(MOD(BB9,60),"00.00")) | P9: =IF(BC9="","",INT(BC9/60)&":"&TEXT(MOD(BC9,60),"00.00")) | Q9: =IF(BD9="","",INT(BD9/60)&":"&TEXT(MOD(BD9,60),"00.00")) | R9: =IF(OR(BB9="",BE9=""),"",(BB9-BE9)/BE9) | S9: =IF(OR(BA9="",BB9=""),"",BB9/(2*BA9)-1) | T9: =IF(OR(BB9="",BD9=""),"",BD9/(4*BB9)-1) | U9: =IF(OR(BC9="",BD9=""),"",INT(((BD9-BC9)/2)/60)&":"&TEXT(MOD((BD9-BC9)/2,60),"00.00")) | V9: =IF(BB9="","",ROUND(BB9,1)) | W9: =IF($A9="","",IFS(BB9="","Pas de T100 valide — Batterie A (T50 + T100).",AND(M9<>"",M9<=3),"Affutage (< 3 sem) — plus de test a fond. Allure de course.",AND(S9<>"",S9>0.1),"Vitesse OK, il casse sur 100 (lactique / pacing / technique).",AND(T9<>"",T9>0.12),"Manque aerobie / seuil — Batterie B (T200+T400) et series CSS.",AND(T9<>"",T9<0.06,S9<>"",S9<0.08),"Profil homogene — specificite d'allure vers la cible.",BA9="","Ajouter un T50 a la prochaine Batterie A.",TRUE,"Profil coherent. Voir consigne_charge pour deload / retest.")) | X9: =IF($A9="","",COUNTIFS(tblSeances[id_nageur],$A9,tblSeances[lundi],(TODAY()-WEEKDAY(TODAY(),3)),tblSeances[faite],"oui")&"/"&IFERROR(INDEX(tblNageurs[seances_sem],MATCH($A9,tblNageurs[id],0)),"")) | Y9: =IF($A9="","",SUMIFS(tblSeances[volume_m],tblSeances[id_nageur],$A9,tblSeances[lundi],(TODAY()-WEEKDAY(TODAY(),3)),tblSeances[faite],"oui")) | Z9: =IF($A9="","",TEXT(SUMIFS(tblSeances[volume_m],tblSeances[id_nageur],$A9,tblSeances[lundi],(TODAY()-WEEKDAY(TODAY(),3)),tblSeances[faite],"oui"),"0")&" / "&TEXT(SUMIFS(tblSeances[volume_m],tblSeances[id_nageur],$A9,tblSeances[lundi],(TODAY()-WEEKDAY(TODAY(),3))-7,tblSeances[faite],"oui"),"0")&" / "&TEXT(SUMIFS(tblSeances[volume_m],tblSeances[id_nageur],$A9,tblSeances[lundi],(TODAY()-WEEKDAY(TODAY(),3))-14,tblSeances[faite],"oui"),"0")) | AA9: =IF($A9="","",IFERROR(INDEX(FILTER(CHARGE!L$3:L$82,(CHARGE!A$3:A$82=$A9)*(CHARGE!B$3:B$82=(TODAY()-WEEKDAY(TODAY(),3)))),1),"")) | AB9: =IF($A9="","",IFERROR(INDEX(FILTER(CHARGE!M$3:M$82,(CHARGE!A$3:A$82=$A9)*(CHARGE!B$3:B$82=(TODAY()-WEEKDAY(TODAY(),3)))),1),"")) | AC9: =IF($A9="","",IFERROR(INDEX(FILTER(CHARGE!N$3:N$82,(CHARGE!A$3:A$82=$A9)*(CHARGE!B$3:B$82=(TODAY()-WEEKDAY(TODAY(),3)))),1),"")) | BA9: =IF($A9="","",IFERROR(INDEX(FILTER(tblTests[temps_sec],(tblTests[id_nageur]=$A9)*(tblTests[protocole]="T50")*(tblTests[nage]=$F9)*(tblTests[valide]="oui")*(tblTests[date]=MAXIFS(tblTests[date],tblTests[id_nageur],$A9,tblTests[protocole],"T50",tblTests[nage],$F9,tblTests[valide],"oui"))),1),"")) | BB9: =IF($A9="","",IFERROR(INDEX(FILTER(tblTests[temps_sec],(tblTests[id_nageur]=$A9)*(tblTests[protocole]="T100")*(tblTests[nage]=$F9)*(tblTests[valide]="oui")*(tblTests[date]=MAXIFS(tblTests[date],tblTests[id_nageur],$A9,tblTests[protocole],"T100",tblTests[nage],$F9,tblTests[valide],"oui"))),1),"")) | BC9: =IF($A9="","",IFERROR(INDEX(FILTER(tblTests[temps_sec],(tblTests[id_nageur]=$A9)*(tblTests[protocole]="T200")*(tblTests[nage]=$F9)*(tblTests[valide]="oui")*(tblTests[date]=MAXIFS(tblTests[date],tblTests[id_nageur],$A9,tblTests[protocole],"T200",tblTests[nage],$F9,tblTests[valide],"oui"))),1),"")) | BD9: =IF($A9="","",IFERROR(INDEX(FILTER(tblTests[temps_sec],(tblTests[id_nageur]=$A9)*(tblTests[protocole]="T400")*(tblTests[nage]=$F9)*(tblTests[valide]="oui")*(tblTests[date]=MAXIFS(tblTests[date],tblTests[id_nageur],$A9,tblTests[protocole],"T400",tblTests[nage],$F9,tblTests[valide],"oui"))),1),"")) | BE9: =IF($A9="","",IFERROR(INDEX(FILTER(tblTests[temps_sec],(tblTests[id_nageur]=$A9)*(tblTests[protocole]="T100")*(tblTests[nage]=$F9)*(tblTests[valide]="oui")*(tblTests[date]=IFERROR(LARGE(FILTER(tblTests[date],(tblTests[id_nageur]=$A9)*(tblTests[protocole]="T100")*(tblTests[nage]=$F9)*(tblTests[valide]="oui")),2),0))),1),"")) | BF9: =IF($A9="","",IFERROR(MAXIFS(tblTests[date],tblTests[id_nageur],$A9,tblTests[protocole],"T100",tblTests[nage],$F9,tblTests[valide],"oui"),""))
A10: =IFERROR(IF(INDEX(tblNageurs[id],8)="","",INDEX(tblNageurs[id],8)),"") | B10: =IF($A10="","",IFERROR(INDEX(tblNageurs[prenom],8),"")) | C10: =IF($A10="","",IFERROR(INDEX(tblNageurs[nom],8),"")) | D10: =IF($A10="","",IFERROR(INDEX(tblNageurs[niveau],8),"")) | E10: =IF($A10="","",IFERROR(INDEX(tblNageurs[statut],8),"")) | F10: =IF($A10="","",IF(OR($H10="dos",$H10="brasse",$H10="papillon"),$H10,"crawl")) | G10: =IF($A10="","",IFERROR(XLOOKUP($A10,tblObjectifs[cle_dashboard],tblObjectifs[discipline],""),"")) | H10: =IF($A10="","",IFERROR(XLOOKUP($A10,tblObjectifs[cle_dashboard],tblObjectifs[nage],""),"")) | I10: =IF($A10="","",IFERROR(XLOOKUP($A10,tblObjectifs[cle_dashboard],tblObjectifs[distance_m],""),"")) | J10: =IF($A10="","",IFERROR(XLOOKUP($A10,tblObjectifs[cle_dashboard],tblObjectifs[date_objectif],""),"")) | K10: =IF($A10="","",IFERROR(XLOOKUP($A10,tblObjectifs[cle_dashboard],tblObjectifs[lieu],""),"")) | L10: =IF($A10="","",IFERROR(XLOOKUP($A10,tblObjectifs[cle_dashboard],tblObjectifs[temps_cible],""),"")) | M10: =IF(OR($A10="",$J10=""),"",($J10-TODAY())/7) | N10: =IF(BA10="","",INT(BA10/60)&":"&TEXT(MOD(BA10,60),"00.00")) | O10: =IF(BB10="","",INT(BB10/60)&":"&TEXT(MOD(BB10,60),"00.00")) | P10: =IF(BC10="","",INT(BC10/60)&":"&TEXT(MOD(BC10,60),"00.00")) | Q10: =IF(BD10="","",INT(BD10/60)&":"&TEXT(MOD(BD10,60),"00.00")) | R10: =IF(OR(BB10="",BE10=""),"",(BB10-BE10)/BE10) | S10: =IF(OR(BA10="",BB10=""),"",BB10/(2*BA10)-1) | T10: =IF(OR(BB10="",BD10=""),"",BD10/(4*BB10)-1) | U10: =IF(OR(BC10="",BD10=""),"",INT(((BD10-BC10)/2)/60)&":"&TEXT(MOD((BD10-BC10)/2,60),"00.00")) | V10: =IF(BB10="","",ROUND(BB10,1)) | W10: =IF($A10="","",IFS(BB10="","Pas de T100 valide — Batterie A (T50 + T100).",AND(M10<>"",M10<=3),"Affutage (< 3 sem) — plus de test a fond. Allure de course.",AND(S10<>"",S10>0.1),"Vitesse OK, il casse sur 100 (lactique / pacing / technique).",AND(T10<>"",T10>0.12),"Manque aerobie / seuil — Batterie B (T200+T400) et series CSS.",AND(T10<>"",T10<0.06,S10<>"",S10<0.08),"Profil homogene — specificite d'allure vers la cible.",BA10="","Ajouter un T50 a la prochaine Batterie A.",TRUE,"Profil coherent. Voir consigne_charge pour deload / retest.")) | X10: =IF($A10="","",COUNTIFS(tblSeances[id_nageur],$A10,tblSeances[lundi],(TODAY()-WEEKDAY(TODAY(),3)),tblSeances[faite],"oui")&"/"&IFERROR(INDEX(tblNageurs[seances_sem],MATCH($A10,tblNageurs[id],0)),"")) | Y10: =IF($A10="","",SUMIFS(tblSeances[volume_m],tblSeances[id_nageur],$A10,tblSeances[lundi],(TODAY()-WEEKDAY(TODAY(),3)),tblSeances[faite],"oui")) | Z10: =IF($A10="","",TEXT(SUMIFS(tblSeances[volume_m],tblSeances[id_nageur],$A10,tblSeances[lundi],(TODAY()-WEEKDAY(TODAY(),3)),tblSeances[faite],"oui"),"0")&" / "&TEXT(SUMIFS(tblSeances[volume_m],tblSeances[id_nageur],$A10,tblSeances[lundi],(TODAY()-WEEKDAY(TODAY(),3))-7,tblSeances[faite],"oui"),"0")&" / "&TEXT(SUMIFS(tblSeances[volume_m],tblSeances[id_nageur],$A10,tblSeances[lundi],(TODAY()-WEEKDAY(TODAY(),3))-14,tblSeances[faite],"oui"),"0")) | AA10: =IF($A10="","",IFERROR(INDEX(FILTER(CHARGE!L$3:L$82,(CHARGE!A$3:A$82=$A10)*(CHARGE!B$3:B$82=(TODAY()-WEEKDAY(TODAY(),3)))),1),"")) | AB10: =IF($A10="","",IFERROR(INDEX(FILTER(CHARGE!M$3:M$82,(CHARGE!A$3:A$82=$A10)*(CHARGE!B$3:B$82=(TODAY()-WEEKDAY(TODAY(),3)))),1),"")) | AC10: =IF($A10="","",IFERROR(INDEX(FILTER(CHARGE!N$3:N$82,(CHARGE!A$3:A$82=$A10)*(CHARGE!B$3:B$82=(TODAY()-WEEKDAY(TODAY(),3)))),1),"")) | BA10: =IF($A10="","",IFERROR(INDEX(FILTER(tblTests[temps_sec],(tblTests[id_nageur]=$A10)*(tblTests[protocole]="T50")*(tblTests[nage]=$F10)*(tblTests[valide]="oui")*(tblTests[date]=MAXIFS(tblTests[date],tblTests[id_nageur],$A10,tblTests[protocole],"T50",tblTests[nage],$F10,tblTests[valide],"oui"))),1),"")) | BB10: =IF($A10="","",IFERROR(INDEX(FILTER(tblTests[temps_sec],(tblTests[id_nageur]=$A10)*(tblTests[protocole]="T100")*(tblTests[nage]=$F10)*(tblTests[valide]="oui")*(tblTests[date]=MAXIFS(tblTests[date],tblTests[id_nageur],$A10,tblTests[protocole],"T100",tblTests[nage],$F10,tblTests[valide],"oui"))),1),"")) | BC10: =IF($A10="","",IFERROR(INDEX(FILTER(tblTests[temps_sec],(tblTests[id_nageur]=$A10)*(tblTests[protocole]="T200")*(tblTests[nage]=$F10)*(tblTests[valide]="oui")*(tblTests[date]=MAXIFS(tblTests[date],tblTests[id_nageur],$A10,tblTests[protocole],"T200",tblTests[nage],$F10,tblTests[valide],"oui"))),1),"")) | BD10: =IF($A10="","",IFERROR(INDEX(FILTER(tblTests[temps_sec],(tblTests[id_nageur]=$A10)*(tblTests[protocole]="T400")*(tblTests[nage]=$F10)*(tblTests[valide]="oui")*(tblTests[date]=MAXIFS(tblTests[date],tblTests[id_nageur],$A10,tblTests[protocole],"T400",tblTests[nage],$F10,tblTests[valide],"oui"))),1),"")) | BE10: =IF($A10="","",IFERROR(INDEX(FILTER(tblTests[temps_sec],(tblTests[id_nageur]=$A10)*(tblTests[protocole]="T100")*(tblTests[nage]=$F10)*(tblTests[valide]="oui")*(tblTests[date]=IFERROR(LARGE(FILTER(tblTests[date],(tblTests[id_nageur]=$A10)*(tblTests[protocole]="T100")*(tblTests[nage]=$F10)*(tblTests[valide]="oui")),2),0))),1),"")) | BF10: =IF($A10="","",IFERROR(MAXIFS(tblTests[date],tblTests[id_nageur],$A10,tblTests[protocole],"T100",tblTests[nage],$F10,tblTests[valide],"oui"),""))
A11: =IFERROR(IF(INDEX(tblNageurs[id],9)="","",INDEX(tblNageurs[id],9)),"") | B11: =IF($A11="","",IFERROR(INDEX(tblNageurs[prenom],9),"")) | C11: =IF($A11="","",IFERROR(INDEX(tblNageurs[nom],9),"")) | D11: =IF($A11="","",IFERROR(INDEX(tblNageurs[niveau],9),"")) | E11: =IF($A11="","",IFERROR(INDEX(tblNageurs[statut],9),"")) | F11: =IF($A11="","",IF(OR($H11="dos",$H11="brasse",$H11="papillon"),$H11,"crawl")) | G11: =IF($A11="","",IFERROR(XLOOKUP($A11,tblObjectifs[cle_dashboard],tblObjectifs[discipline],""),"")) | H11: =IF($A11="","",IFERROR(XLOOKUP($A11,tblObjectifs[cle_dashboard],tblObjectifs[nage],""),"")) | I11: =IF($A11="","",IFERROR(XLOOKUP($A11,tblObjectifs[cle_dashboard],tblObjectifs[distance_m],""),"")) | J11: =IF($A11="","",IFERROR(XLOOKUP($A11,tblObjectifs[cle_dashboard],tblObjectifs[date_objectif],""),"")) | K11: =IF($A11="","",IFERROR(XLOOKUP($A11,tblObjectifs[cle_dashboard],tblObjectifs[lieu],""),"")) | L11: =IF($A11="","",IFERROR(XLOOKUP($A11,tblObjectifs[cle_dashboard],tblObjectifs[temps_cible],""),"")) | M11: =IF(OR($A11="",$J11=""),"",($J11-TODAY())/7) | N11: =IF(BA11="","",INT(BA11/60)&":"&TEXT(MOD(BA11,60),"00.00")) | O11: =IF(BB11="","",INT(BB11/60)&":"&TEXT(MOD(BB11,60),"00.00")) | P11: =IF(BC11="","",INT(BC11/60)&":"&TEXT(MOD(BC11,60),"00.00")) | Q11: =IF(BD11="","",INT(BD11/60)&":"&TEXT(MOD(BD11,60),"00.00")) | R11: =IF(OR(BB11="",BE11=""),"",(BB11-BE11)/BE11) | S11: =IF(OR(BA11="",BB11=""),"",BB11/(2*BA11)-1) | T11: =IF(OR(BB11="",BD11=""),"",BD11/(4*BB11)-1) | U11: =IF(OR(BC11="",BD11=""),"",INT(((BD11-BC11)/2)/60)&":"&TEXT(MOD((BD11-BC11)/2,60),"00.00")) | V11: =IF(BB11="","",ROUND(BB11,1)) | W11: =IF($A11="","",IFS(BB11="","Pas de T100 valide — Batterie A (T50 + T100).",AND(M11<>"",M11<=3),"Affutage (< 3 sem) — plus de test a fond. Allure de course.",AND(S11<>"",S11>0.1),"Vitesse OK, il casse sur 100 (lactique / pacing / technique).",AND(T11<>"",T11>0.12),"Manque aerobie / seuil — Batterie B (T200+T400) et series CSS.",AND(T11<>"",T11<0.06,S11<>"",S11<0.08),"Profil homogene — specificite d'allure vers la cible.",BA11="","Ajouter un T50 a la prochaine Batterie A.",TRUE,"Profil coherent. Voir consigne_charge pour deload / retest.")) | X11: =IF($A11="","",COUNTIFS(tblSeances[id_nageur],$A11,tblSeances[lundi],(TODAY()-WEEKDAY(TODAY(),3)),tblSeances[faite],"oui")&"/"&IFERROR(INDEX(tblNageurs[seances_sem],MATCH($A11,tblNageurs[id],0)),"")) | Y11: =IF($A11="","",SUMIFS(tblSeances[volume_m],tblSeances[id_nageur],$A11,tblSeances[lundi],(TODAY()-WEEKDAY(TODAY(),3)),tblSeances[faite],"oui")) | Z11: =IF($A11="","",TEXT(SUMIFS(tblSeances[volume_m],tblSeances[id_nageur],$A11,tblSeances[lundi],(TODAY()-WEEKDAY(TODAY(),3)),tblSeances[faite],"oui"),"0")&" / "&TEXT(SUMIFS(tblSeances[volume_m],tblSeances[id_nageur],$A11,tblSeances[lundi],(TODAY()-WEEKDAY(TODAY(),3))-7,tblSeances[faite],"oui"),"0")&" / "&TEXT(SUMIFS(tblSeances[volume_m],tblSeances[id_nageur],$A11,tblSeances[lundi],(TODAY()-WEEKDAY(TODAY(),3))-14,tblSeances[faite],"oui"),"0")) | AA11: =IF($A11="","",IFERROR(INDEX(FILTER(CHARGE!L$3:L$82,(CHARGE!A$3:A$82=$A11)*(CHARGE!B$3:B$82=(TODAY()-WEEKDAY(TODAY(),3)))),1),"")) | AB11: =IF($A11="","",IFERROR(INDEX(FILTER(CHARGE!M$3:M$82,(CHARGE!A$3:A$82=$A11)*(CHARGE!B$3:B$82=(TODAY()-WEEKDAY(TODAY(),3)))),1),"")) | AC11: =IF($A11="","",IFERROR(INDEX(FILTER(CHARGE!N$3:N$82,(CHARGE!A$3:A$82=$A11)*(CHARGE!B$3:B$82=(TODAY()-WEEKDAY(TODAY(),3)))),1),"")) | BA11: =IF($A11="","",IFERROR(INDEX(FILTER(tblTests[temps_sec],(tblTests[id_nageur]=$A11)*(tblTests[protocole]="T50")*(tblTests[nage]=$F11)*(tblTests[valide]="oui")*(tblTests[date]=MAXIFS(tblTests[date],tblTests[id_nageur],$A11,tblTests[protocole],"T50",tblTests[nage],$F11,tblTests[valide],"oui"))),1),"")) | BB11: =IF($A11="","",IFERROR(INDEX(FILTER(tblTests[temps_sec],(tblTests[id_nageur]=$A11)*(tblTests[protocole]="T100")*(tblTests[nage]=$F11)*(tblTests[valide]="oui")*(tblTests[date]=MAXIFS(tblTests[date],tblTests[id_nageur],$A11,tblTests[protocole],"T100",tblTests[nage],$F11,tblTests[valide],"oui"))),1),"")) | BC11: =IF($A11="","",IFERROR(INDEX(FILTER(tblTests[temps_sec],(tblTests[id_nageur]=$A11)*(tblTests[protocole]="T200")*(tblTests[nage]=$F11)*(tblTests[valide]="oui")*(tblTests[date]=MAXIFS(tblTests[date],tblTests[id_nageur],$A11,tblTests[protocole],"T200",tblTests[nage],$F11,tblTests[valide],"oui"))),1),"")) | BD11: =IF($A11="","",IFERROR(INDEX(FILTER(tblTests[temps_sec],(tblTests[id_nageur]=$A11)*(tblTests[protocole]="T400")*(tblTests[nage]=$F11)*(tblTests[valide]="oui")*(tblTests[date]=MAXIFS(tblTests[date],tblTests[id_nageur],$A11,tblTests[protocole],"T400",tblTests[nage],$F11,tblTests[valide],"oui"))),1),"")) | BE11: =IF($A11="","",IFERROR(INDEX(FILTER(tblTests[temps_sec],(tblTests[id_nageur]=$A11)*(tblTests[protocole]="T100")*(tblTests[nage]=$F11)*(tblTests[valide]="oui")*(tblTests[date]=IFERROR(LARGE(FILTER(tblTests[date],(tblTests[id_nageur]=$A11)*(tblTests[protocole]="T100")*(tblTests[nage]=$F11)*(tblTests[valide]="oui")),2),0))),1),"")) | BF11: =IF($A11="","",IFERROR(MAXIFS(tblTests[date],tblTests[id_nageur],$A11,tblTests[protocole],"T100",tblTests[nage],$F11,tblTests[valide],"oui"),""))
A12: =IFERROR(IF(INDEX(tblNageurs[id],10)="","",INDEX(tblNageurs[id],10)),"") | B12: =IF($A12="","",IFERROR(INDEX(tblNageurs[prenom],10),"")) | C12: =IF($A12="","",IFERROR(INDEX(tblNageurs[nom],10),"")) | D12: =IF($A12="","",IFERROR(INDEX(tblNageurs[niveau],10),"")) | E12: =IF($A12="","",IFERROR(INDEX(tblNageurs[statut],10),"")) | F12: =IF($A12="","",IF(OR($H12="dos",$H12="brasse",$H12="papillon"),$H12,"crawl")) | G12: =IF($A12="","",IFERROR(XLOOKUP($A12,tblObjectifs[cle_dashboard],tblObjectifs[discipline],""),"")) | H12: =IF($A12="","",IFERROR(XLOOKUP($A12,tblObjectifs[cle_dashboard],tblObjectifs[nage],""),"")) | I12: =IF($A12="","",IFERROR(XLOOKUP($A12,tblObjectifs[cle_dashboard],tblObjectifs[distance_m],""),"")) | J12: =IF($A12="","",IFERROR(XLOOKUP($A12,tblObjectifs[cle_dashboard],tblObjectifs[date_objectif],""),"")) | K12: =IF($A12="","",IFERROR(XLOOKUP($A12,tblObjectifs[cle_dashboard],tblObjectifs[lieu],""),"")) | L12: =IF($A12="","",IFERROR(XLOOKUP($A12,tblObjectifs[cle_dashboard],tblObjectifs[temps_cible],""),"")) | M12: =IF(OR($A12="",$J12=""),"",($J12-TODAY())/7) | N12: =IF(BA12="","",INT(BA12/60)&":"&TEXT(MOD(BA12,60),"00.00")) | O12: =IF(BB12="","",INT(BB12/60)&":"&TEXT(MOD(BB12,60),"00.00")) | P12: =IF(BC12="","",INT(BC12/60)&":"&TEXT(MOD(BC12,60),"00.00")) | Q12: =IF(BD12="","",INT(BD12/60)&":"&TEXT(MOD(BD12,60),"00.00")) | R12: =IF(OR(BB12="",BE12=""),"",(BB12-BE12)/BE12) | S12: =IF(OR(BA12="",BB12=""),"",BB12/(2*BA12)-1) | T12: =IF(OR(BB12="",BD12=""),"",BD12/(4*BB12)-1) | U12: =IF(OR(BC12="",BD12=""),"",INT(((BD12-BC12)/2)/60)&":"&TEXT(MOD((BD12-BC12)/2,60),"00.00")) | V12: =IF(BB12="","",ROUND(BB12,1)) | W12: =IF($A12="","",IFS(BB12="","Pas de T100 valide — Batterie A (T50 + T100).",AND(M12<>"",M12<=3),"Affutage (< 3 sem) — plus de test a fond. Allure de course.",AND(S12<>"",S12>0.1),"Vitesse OK, il casse sur 100 (lactique / pacing / technique).",AND(T12<>"",T12>0.12),"Manque aerobie / seuil — Batterie B (T200+T400) et series CSS.",AND(T12<>"",T12<0.06,S12<>"",S12<0.08),"Profil homogene — specificite d'allure vers la cible.",BA12="","Ajouter un T50 a la prochaine Batterie A.",TRUE,"Profil coherent. Voir consigne_charge pour deload / retest.")) | X12: =IF($A12="","",COUNTIFS(tblSeances[id_nageur],$A12,tblSeances[lundi],(TODAY()-WEEKDAY(TODAY(),3)),tblSeances[faite],"oui")&"/"&IFERROR(INDEX(tblNageurs[seances_sem],MATCH($A12,tblNageurs[id],0)),"")) | Y12: =IF($A12="","",SUMIFS(tblSeances[volume_m],tblSeances[id_nageur],$A12,tblSeances[lundi],(TODAY()-WEEKDAY(TODAY(),3)),tblSeances[faite],"oui")) | Z12: =IF($A12="","",TEXT(SUMIFS(tblSeances[volume_m],tblSeances[id_nageur],$A12,tblSeances[lundi],(TODAY()-WEEKDAY(TODAY(),3)),tblSeances[faite],"oui"),"0")&" / "&TEXT(SUMIFS(tblSeances[volume_m],tblSeances[id_nageur],$A12,tblSeances[lundi],(TODAY()-WEEKDAY(TODAY(),3))-7,tblSeances[faite],"oui"),"0")&" / "&TEXT(SUMIFS(tblSeances[volume_m],tblSeances[id_nageur],$A12,tblSeances[lundi],(TODAY()-WEEKDAY(TODAY(),3))-14,tblSeances[faite],"oui"),"0")) | AA12: =IF($A12="","",IFERROR(INDEX(FILTER(CHARGE!L$3:L$82,(CHARGE!A$3:A$82=$A12)*(CHARGE!B$3:B$82=(TODAY()-WEEKDAY(TODAY(),3)))),1),"")) | AB12: =IF($A12="","",IFERROR(INDEX(FILTER(CHARGE!M$3:M$82,(CHARGE!A$3:A$82=$A12)*(CHARGE!B$3:B$82=(TODAY()-WEEKDAY(TODAY(),3)))),1),"")) | AC12: =IF($A12="","",IFERROR(INDEX(FILTER(CHARGE!N$3:N$82,(CHARGE!A$3:A$82=$A12)*(CHARGE!B$3:B$82=(TODAY()-WEEKDAY(TODAY(),3)))),1),"")) | BA12: =IF($A12="","",IFERROR(INDEX(FILTER(tblTests[temps_sec],(tblTests[id_nageur]=$A12)*(tblTests[protocole]="T50")*(tblTests[nage]=$F12)*(tblTests[valide]="oui")*(tblTests[date]=MAXIFS(tblTests[date],tblTests[id_nageur],$A12,tblTests[protocole],"T50",tblTests[nage],$F12,tblTests[valide],"oui"))),1),"")) | BB12: =IF($A12="","",IFERROR(INDEX(FILTER(tblTests[temps_sec],(tblTests[id_nageur]=$A12)*(tblTests[protocole]="T100")*(tblTests[nage]=$F12)*(tblTests[valide]="oui")*(tblTests[date]=MAXIFS(tblTests[date],tblTests[id_nageur],$A12,tblTests[protocole],"T100",tblTests[nage],$F12,tblTests[valide],"oui"))),1),"")) | BC12: =IF($A12="","",IFERROR(INDEX(FILTER(tblTests[temps_sec],(tblTests[id_nageur]=$A12)*(tblTests[protocole]="T200")*(tblTests[nage]=$F12)*(tblTests[valide]="oui")*(tblTests[date]=MAXIFS(tblTests[date],tblTests[id_nageur],$A12,tblTests[protocole],"T200",tblTests[nage],$F12,tblTests[valide],"oui"))),1),"")) | BD12: =IF($A12="","",IFERROR(INDEX(FILTER(tblTests[temps_sec],(tblTests[id_nageur]=$A12)*(tblTests[protocole]="T400")*(tblTests[nage]=$F12)*(tblTests[valide]="oui")*(tblTests[date]=MAXIFS(tblTests[date],tblTests[id_nageur],$A12,tblTests[protocole],"T400",tblTests[nage],$F12,tblTests[valide],"oui"))),1),"")) | BE12: =IF($A12="","",IFERROR(INDEX(FILTER(tblTests[temps_sec],(tblTests[id_nageur]=$A12)*(tblTests[protocole]="T100")*(tblTests[nage]=$F12)*(tblTests[valide]="oui")*(tblTests[date]=IFERROR(LARGE(FILTER(tblTests[date],(tblTests[id_nageur]=$A12)*(tblTests[protocole]="T100")*(tblTests[nage]=$F12)*(tblTests[valide]="oui")),2),0))),1),"")) | BF12: =IF($A12="","",IFERROR(MAXIFS(tblTests[date],tblTests[id_nageur],$A12,tblTests[protocole],"T100",tblTests[nage],$F12,tblTests[valide],"oui"),""))
A13: =IFERROR(IF(INDEX(tblNageurs[id],11)="","",INDEX(tblNageurs[id],11)),"") | B13: =IF($A13="","",IFERROR(INDEX(tblNageurs[prenom],11),"")) | C13: =IF($A13="","",IFERROR(INDEX(tblNageurs[nom],11),"")) | D13: =IF($A13="","",IFERROR(INDEX(tblNageurs[niveau],11),"")) | E13: =IF($A13="","",IFERROR(INDEX(tblNageurs[statut],11),"")) | F13: =IF($A13="","",IF(OR($H13="dos",$H13="brasse",$H13="papillon"),$H13,"crawl")) | G13: =IF($A13="","",IFERROR(XLOOKUP($A13,tblObjectifs[cle_dashboard],tblObjectifs[discipline],""),"")) | H13: =IF($A13="","",IFERROR(XLOOKUP($A13,tblObjectifs[cle_dashboard],tblObjectifs[nage],""),"")) | I13: =IF($A13="","",IFERROR(XLOOKUP($A13,tblObjectifs[cle_dashboard],tblObjectifs[distance_m],""),"")) | J13: =IF($A13="","",IFERROR(XLOOKUP($A13,tblObjectifs[cle_dashboard],tblObjectifs[date_objectif],""),"")) | K13: =IF($A13="","",IFERROR(XLOOKUP($A13,tblObjectifs[cle_dashboard],tblObjectifs[lieu],""),"")) | L13: =IF($A13="","",IFERROR(XLOOKUP($A13,tblObjectifs[cle_dashboard],tblObjectifs[temps_cible],""),"")) | M13: =IF(OR($A13="",$J13=""),"",($J13-TODAY())/7) | N13: =IF(BA13="","",INT(BA13/60)&":"&TEXT(MOD(BA13,60),"00.00")) | O13: =IF(BB13="","",INT(BB13/60)&":"&TEXT(MOD(BB13,60),"00.00")) | P13: =IF(BC13="","",INT(BC13/60)&":"&TEXT(MOD(BC13,60),"00.00")) | Q13: =IF(BD13="","",INT(BD13/60)&":"&TEXT(MOD(BD13,60),"00.00")) | R13: =IF(OR(BB13="",BE13=""),"",(BB13-BE13)/BE13) | S13: =IF(OR(BA13="",BB13=""),"",BB13/(2*BA13)-1) | T13: =IF(OR(BB13="",BD13=""),"",BD13/(4*BB13)-1) | U13: =IF(OR(BC13="",BD13=""),"",INT(((BD13-BC13)/2)/60)&":"&TEXT(MOD((BD13-BC13)/2,60),"00.00")) | V13: =IF(BB13="","",ROUND(BB13,1)) | W13: =IF($A13="","",IFS(BB13="","Pas de T100 valide — Batterie A (T50 + T100).",AND(M13<>"",M13<=3),"Affutage (< 3 sem) — plus de test a fond. Allure de course.",AND(S13<>"",S13>0.1),"Vitesse OK, il casse sur 100 (lactique / pacing / technique).",AND(T13<>"",T13>0.12),"Manque aerobie / seuil — Batterie B (T200+T400) et series CSS.",AND(T13<>"",T13<0.06,S13<>"",S13<0.08),"Profil homogene — specificite d'allure vers la cible.",BA13="","Ajouter un T50 a la prochaine Batterie A.",TRUE,"Profil coherent. Voir consigne_charge pour deload / retest.")) | X13: =IF($A13="","",COUNTIFS(tblSeances[id_nageur],$A13,tblSeances[lundi],(TODAY()-WEEKDAY(TODAY(),3)),tblSeances[faite],"oui")&"/"&IFERROR(INDEX(tblNageurs[seances_sem],MATCH($A13,tblNageurs[id],0)),"")) | Y13: =IF($A13="","",SUMIFS(tblSeances[volume_m],tblSeances[id_nageur],$A13,tblSeances[lundi],(TODAY()-WEEKDAY(TODAY(),3)),tblSeances[faite],"oui")) | Z13: =IF($A13="","",TEXT(SUMIFS(tblSeances[volume_m],tblSeances[id_nageur],$A13,tblSeances[lundi],(TODAY()-WEEKDAY(TODAY(),3)),tblSeances[faite],"oui"),"0")&" / "&TEXT(SUMIFS(tblSeances[volume_m],tblSeances[id_nageur],$A13,tblSeances[lundi],(TODAY()-WEEKDAY(TODAY(),3))-7,tblSeances[faite],"oui"),"0")&" / "&TEXT(SUMIFS(tblSeances[volume_m],tblSeances[id_nageur],$A13,tblSeances[lundi],(TODAY()-WEEKDAY(TODAY(),3))-14,tblSeances[faite],"oui"),"0")) | AA13: =IF($A13="","",IFERROR(INDEX(FILTER(CHARGE!L$3:L$82,(CHARGE!A$3:A$82=$A13)*(CHARGE!B$3:B$82=(TODAY()-WEEKDAY(TODAY(),3)))),1),"")) | AB13: =IF($A13="","",IFERROR(INDEX(FILTER(CHARGE!M$3:M$82,(CHARGE!A$3:A$82=$A13)*(CHARGE!B$3:B$82=(TODAY()-WEEKDAY(TODAY(),3)))),1),"")) | AC13: =IF($A13="","",IFERROR(INDEX(FILTER(CHARGE!N$3:N$82,(CHARGE!A$3:A$82=$A13)*(CHARGE!B$3:B$82=(TODAY()-WEEKDAY(TODAY(),3)))),1),"")) | BA13: =IF($A13="","",IFERROR(INDEX(FILTER(tblTests[temps_sec],(tblTests[id_nageur]=$A13)*(tblTests[protocole]="T50")*(tblTests[nage]=$F13)*(tblTests[valide]="oui")*(tblTests[date]=MAXIFS(tblTests[date],tblTests[id_nageur],$A13,tblTests[protocole],"T50",tblTests[nage],$F13,tblTests[valide],"oui"))),1),"")) | BB13: =IF($A13="","",IFERROR(INDEX(FILTER(tblTests[temps_sec],(tblTests[id_nageur]=$A13)*(tblTests[protocole]="T100")*(tblTests[nage]=$F13)*(tblTests[valide]="oui")*(tblTests[date]=MAXIFS(tblTests[date],tblTests[id_nageur],$A13,tblTests[protocole],"T100",tblTests[nage],$F13,tblTests[valide],"oui"))),1),"")) | BC13: =IF($A13="","",IFERROR(INDEX(FILTER(tblTests[temps_sec],(tblTests[id_nageur]=$A13)*(tblTests[protocole]="T200")*(tblTests[nage]=$F13)*(tblTests[valide]="oui")*(tblTests[date]=MAXIFS(tblTests[date],tblTests[id_nageur],$A13,tblTests[protocole],"T200",tblTests[nage],$F13,tblTests[valide],"oui"))),1),"")) | BD13: =IF($A13="","",IFERROR(INDEX(FILTER(tblTests[temps_sec],(tblTests[id_nageur]=$A13)*(tblTests[protocole]="T400")*(tblTests[nage]=$F13)*(tblTests[valide]="oui")*(tblTests[date]=MAXIFS(tblTests[date],tblTests[id_nageur],$A13,tblTests[protocole],"T400",tblTests[nage],$F13,tblTests[valide],"oui"))),1),"")) | BE13: =IF($A13="","",IFERROR(INDEX(FILTER(tblTests[temps_sec],(tblTests[id_nageur]=$A13)*(tblTests[protocole]="T100")*(tblTests[nage]=$F13)*(tblTests[valide]="oui")*(tblTests[date]=IFERROR(LARGE(FILTER(tblTests[date],(tblTests[id_nageur]=$A13)*(tblTests[protocole]="T100")*(tblTests[nage]=$F13)*(tblTests[valide]="oui")),2),0))),1),"")) | BF13: =IF($A13="","",IFERROR(MAXIFS(tblTests[date],tblTests[id_nageur],$A13,tblTests[protocole],"T100",tblTests[nage],$F13,tblTests[valide],"oui"),""))
